Workbook

Sheet 안내
B2: 호호책방 (book_clinic) 기능 정의서
B3: Web(운영관리) · PWA(학생) | 작성일 2026-10-13 | 기준: 소스 코드 현재 상태
B5: 이 문서의 범위
B6: 포함 | C6: ① Web 운영관리 (센터 직원용 관리자 웹) ② PWA (학생용 출석체크·문제풀이)
B7: 제외 | C7: i-with(학부모 앱) 연동: 앱 로그인·책방 메인·정독 결과·예약 API, 결제 체크아웃, 이용권 앱 조회, 정독 달력, 학부모 앱 설치 페이지
B8: 경계 | C8: 독서 결과 발송(W-13)은 Web 화면만 정의했고, 앱 쪽 표시는 제외했습니다.
B10: 시트 안내
B11: 화면목록 | C11: 메뉴 구조 — 어떤 화면이 있고 기능이 몇 개인지 한눈에 보는 시트 (먼저 보세요)
B12: 기능목록 | C12: 화면별 기능을 한 줄씩 정리한 표 — 영역·화면·상태로 필터링 가능
B13: 업무규칙 | C13: 추천·채점·보상·레벨·입퇴실·예약·재고·권한의 핵심 규칙
B14: 코드·용어 | C14: 등급·뱃지·상태값 등 화면에 표시되는 값의 의미
B15: 확인 필요 | C15: 미구현·부분 구현, 정책 불일치, 보안 관찰 항목
B17: 상태 구분
B18: 구현 | C18: 화면과 기능이 모두 동작함
B19: 부분 | C19: 일부만 구현되었거나 확인이 필요함 (비고 참고)
B20: 미구현 | C20: 아직 만들어지지 않음 / 준비 중
B22: 현황 요약 (기능목록 기준 자동 집계)
B23: 영역 | C23: 전체 기능 | D23: 구현 | E23: 부분 | F23: 미구현
B24: Web | C24: =COUNTIF(기능목록!$B$2:$B$141,B24) | D24: =COUNTIFS(기능목록!$B$2:$B$141,$B24,기능목록!$I$2:$I$141,"구현") | E24: =COUNTIFS(기능목록!$B$2:$B$141,$B24,기능목록!$I$2:$I$141,"부분") | F24: =COUNTIFS(기능목록!$B$2:$B$141,$B24,기능목록!$I$2:$I$141,"미구현")
B25: PWA | C25: =COUNTIF(기능목록!$B$2:$B$141,B25) | D25: =COUNTIFS(기능목록!$B$2:$B$141,$B25,기능목록!$I$2:$I$141,"구현") | E25: =COUNTIFS(기능목록!$B$2:$B$141,$B25,기능목록!$I$2:$I$141,"부분") | F25: =COUNTIFS(기능목록!$B$2:$B$141,$B25,기능목록!$I$2:$I$141,"미구현")
B26: 합계 | C26: =SUM(C24:C25) | D26: =SUM(D24:D25) | E26: =SUM(E24:E25) | F26: =SUM(F24:F25)
B28: 읽는 방법
B29: • 처음에는 '화면목록'으로 전체 구조를 보고, 궁금한 화면의 ID(예: W-09)를 '기능목록'에서 필터로 찾으세요.
B30: • 기능 ID는 [화면ID]-[번호] 형식입니다. (예: W-09-07 = 실시간 모니터링의 7번째 기능)
B31: • 여러 화면에 걸친 규칙(추천·채점·예약 등)은 '업무규칙' 시트에 한 번만 정리했습니다.
B32: • 화면 경로 등 시스템 용어는 '화면목록'과 '확인 필요' 시트에만 두었습니다.

Sheet 기능목록
A1: No | B1: 영역 | C1: 대메뉴 | D1: 화면 | E1: 기능ID | F1: 기능명 | G1: 기능 설명 | H1: 사용 권한 | I1: 상태 | J1: 비고 · 주의
A2: 1 | B2: Web | C2: 데이터 관리 | D2: 도서 데이터 관리 | E2: W-01-01 | F2: 도서 목록 조회 | G2: 학년·분류·장르·저자·키워드·사용 여부로 도서를 검색한다. | H2: 전 직원 | I2: 구현
A3: 2 | B3: Web | C3: 데이터 관리 | D3: 도서 데이터 관리 | E3: W-01-02 | F3: 학년별 도서 목록 엑셀 | G3: 학년별 시트(번호·도서명·저자)로 목록을 내려받는다. | H3: 전 직원 | I3: 구현
A4: 3 | B4: Web | C4: 데이터 관리 | D4: 도서 데이터 관리 | E4: W-01-03 | F4: 신규 도서 등록 | G4: 본사는 마스터 도서를, 지점은 '우리 센터 도서'(하위 도서)를 등록한다. | H4: 본사 / 지점 | I4: 구현 | J4: 저장하면 이어서 문제를 입력할 수 있다.
A5: 4 | B5: Web | C5: 데이터 관리 | D5: 도서 데이터 관리 | E5: W-01-04 | F5: 도서 정보 편집 | G5: 도서명·표지·저자·출판사·권장학년·분류·장르·해시태그·독서 예상 시간·난이도·소개를 수정한다. | H5: 본사 | I5: 구현 | J5: 분류가 교과연계/기관추천/인증수상작이면 연계교과/추천기관/수상명을 추가로 입력한다. 표지는 도서 저장 후에 올릴 수 있다.
A6: 5 | B6: Web | C6: 데이터 관리 | D6: 도서 데이터 관리 | E6: W-01-05 | F6: 사용중 / 절판 전환 | G6: 도서를 추천 대상에 포함(사용중)하거나 제외(절판)한다. | H6: 본사 | I6: 구현 | J6: 문제가 등록되지 않은 도서는 사용중으로 바꿀 수 없다.
A7: 6 | B7: Web | C7: 데이터 관리 | D7: 도서 데이터 관리 | E7: W-01-06 | F7: 워크시트 등록·삭제 | G7: 수업에서 출력할 활동지(이미지 또는 PDF)를 등록한다. | H7: 본사 | I7: 구현 | J7: 책당 1개. 등록돼 있어야 모니터링에서 출력할 수 있다.
A8: 7 | B8: Web | C8: 데이터 관리 | D8: 도서 데이터 관리 | E8: W-01-07 | F8: 수집 카드 등록·삭제 | G8: 학생이 문제를 풀면 받는 도서 카드 이미지를 등록한다. | H8: 본사 | I8: 구현 | J8: 책당 1장. 없으면 기본 카드가 나간다.
A9: 8 | B9: Web | C9: 데이터 관리 | D9: 도서 데이터 관리 | E9: W-01-08 | F9: 도서 삭제 · 복구 | G9: 선택한 도서를 삭제하고, '삭제 도서함'에서 복구한다. | H9: 본사 | I9: 구현 | J9: 삭제하면 그 도서의 실물 도서와 문제도 함께 보관함으로 이동한다.
A10: 9 | B10: Web | C10: 데이터 관리 | D10: 도서 데이터 관리 | E10: W-01-09 | F10: 도서 엑셀 일괄 등록·수정 | G10: 양식을 내려받아 수정·추가한 뒤 올린다. 반영 전에 신규/수정/변경없음 건수를 먼저 확인한다. | H10: 본사 | I10: 구현 | J10: 값이 바뀐 행만 수정된다. 양식의 도서번호(content_id) 열은 고치면 안 된다.
A11: 10 | B11: Web | C11: 데이터 관리 | D11: 도서 데이터 관리 | E11: W-01-10 | F11: 센터 보유 도서 관리 | G11: 지점이 우리 센터 도서의 제목·출판사·키워드를 등록·수정·삭제·복구한다. | H11: 지점 | I11: 구현 | J11: 삭제는 우리 센터 보유분만 해당된다.
A12: 11 | B12: Web | C12: 데이터 관리 | D12: 도서 데이터 관리 | E12: W-01-11 | F12: 문제 출제 (기본 / 심화) | G12: 문항별로 문제·지문·보기 4개·정답·유형을 입력한다. | H12: 본사 | I12: 구현 | J12: 기본 문제는 12 또는 15문항이 표준. 문제 글자 서식은 굵게·밑줄·기울임만 가능.
A13: 12 | B13: Web | C13: 데이터 관리 | D13: 도서 데이터 관리 | E13: W-01-12 | F13: 문제 수정 · 삭제 · 복구 | G13: 문항 단위로 고치고 지우고, 삭제한 문항을 되살린다. | H13: 본사 | I13: 구현
A14: 13 | B14: Web | C14: 데이터 관리 | D14: 도서 데이터 관리 | E14: W-01-13 | F14: 문제 엑셀 일괄 등록 | G14: 양식으로 여러 도서의 문제를 한 번에 등록한다. 중복이 있으면 '확인만 / 덮어쓰기 / 비활성으로 등록' 중 선택한다. | H14: 본사 | I14: 구현
A15: 14 | B15: Web | C15: 데이터 관리 | D15: 도서 데이터 관리 | E15: W-01-14 | F15: 권한별 화면 제어 | G15: 지점 직원에게는 마스터 도서·문제를 읽기 전용으로 보여준다. | H15: 지점 | I15: 구현 | J15: 화면에서만 막고 있다. ('확인 필요' 시트 참고)
A16: 15 | B16: Web | C16: 데이터 관리 | D16: 도서 데이터 관리 | E16: W-01-15 | F16: 미저장 이탈 경고 | G16: 수정 중 화면을 벗어나려 하면 확인 창을 띄운다. | H16: 전 직원 | I16: 구현
A17: 16 | B17: Web | C17: 데이터 관리 | D17: 권장도서 순위 | E17: W-02-01 | F17: 학년별 순위 보기 | G17: 초1~중등 7개 탭으로 순위를 보고, 총 등록·사용 가능·절판 도서 수를 확인한다. | H17: 전 직원 | I17: 구현 | J17: 올해 기준으로 적용 중인 순위가 표시된다.
A18: 17 | B18: Web | C18: 데이터 관리 | D18: 권장도서 순위 | E18: W-02-02 | F18: 순위 편집 | G18: 도서를 끌어다 놓아 순서를 바꾼다. | H18: 본사 | I18: 구현
A19: 18 | B19: Web | C19: 데이터 관리 | D19: 권장도서 순위 | E19: W-02-03 | F19: 순위 저장 | G19: '이번 연도 즉시 적용' 또는 '내년 예약'을 골라 저장한다. | H19: 본사 | I19: 구현 | J19: 즉시 적용하면 기존 초안은 모두 정리된다. 예약은 여러 개 저장 가능하며 첫 저장은 자동 적용된다.
A20: 19 | B20: Web | C20: 데이터 관리 | D20: 권장도서 순위 | E20: W-02-04 | F20: 예약 목록 보기 | G20: 저장된 순위 초안 목록과 초안별 순위를 미리 본다. | H20: 전 직원 | I20: 구현
A21: 20 | B21: Web | C21: 데이터 관리 | D21: 권장도서 순위 | E21: W-02-05 | F21: 초안 적용 | G21: 선택한 초안을 적용 중 순위로 바꾼다. | H21: 본사 | I21: 구현 | J21: 같은 연도·학년의 다른 초안은 적용이 해제된다.
A22: 21 | B22: Web | C22: 데이터 관리 | D22: 권장도서 순위 | E22: W-02-06 | F22: 초안 삭제 | G22: 필요 없는 초안을 삭제한다. | H22: 본사 | I22: 구현 | J22: 삭제하면 복구할 수 없다.
A23: 22 | B23: Web | C23: 데이터 관리 | D23: 권장도서 순위 | E23: W-02-07 | F23: 순위 엑셀 다운로드 | G23: 연도별 순위를 학년 7개 시트로 내려받는다. | H23: 전 직원 | I23: 구현
A24: 23 | B24: Web | C24: 데이터 관리 | D24: 레벨/뱃지 관리 | E24: W-03-01 | F24: 레벨/뱃지 관리 | G24: 레벨 기준과 뱃지를 관리하는 기능. | H24: - | I24: 미구현 | J24: '준비 중' 안내 화면만 있다. 현재 레벨 규칙·뱃지는 코드/DB에서 직접 관리한다.
A25: 24 | B25: Web | C25: 운영관리 | D25: 보유도서 설정 | E25: W-04-01 | F25: 보유 도서 조회 | G25: 학년·분류·카테고리·보유 여부·도서명으로 우리 센터 보유 현황을 본다. | H25: 전 직원 | I25: 구현 | J25: 보유 0권인 도서도 함께 나온다. 다른 센터 재고는 볼 수 없다.
A26: 25 | B26: Web | C26: 운영관리 | D26: 보유도서 설정 | E26: W-04-02 | F26: 보유 수량 조정 | G26: +/- 버튼으로 수량을 바꾸면 바로 저장된다. | H26: 전 직원 | I26: 구현 | J26: 줄일 때는 사유를 꼭 입력해야 한다. 대여 중·분실 중인 수량은 줄일 수 없다.
A27: 26 | B27: Web | C27: 운영관리 | D27: 보유도서 설정 | E27: W-04-03 | F27: 판본별 수량 조정 | G27: 도서를 펼쳐 판본(바코드)별로 수량을 따로 조정한다. | H27: 전 직원 | I27: 구현
A28: 27 | B28: Web | C28: 운영관리 | D28: 보유도서 설정 | E28: W-04-04 | F28: 변경 이력 보기 | G28: 수량 변경 전·후, 사유, 일시를 확인한다. | H28: 전 직원 | I28: 구현
A29: 28 | B29: Web | C29: 운영관리 | D29: 보유도서 설정 | E29: W-04-05 | F29: 수량 일괄 등록 | G29: 학년 탭별로 여러 도서의 수량을 입력해 저장한다. | H29: 전 직원 | I29: 구현 | J29: 저장 전에는 탭을 옮겨도 입력값이 유지된다.
A30: 29 | B30: Web | C30: 운영관리 | D30: 보유도서 설정 | E30: W-04-06 | F30: 분실·훼손 재고 복구 | G30: '책이 없음/훼손'으로 뺀 재고를 나중에 찾았을 때 되돌린다. | H30: 전 직원 | I30: 부분 | J30: 기능은 만들어져 있으나 화면 버튼이 없다.
A31: 30 | B31: Web | C31: 운영관리 | D31: 운영 스케줄 | E31: W-05-01 | F31: 요일별 운영 설정 보기 | G31: 월~일 요일별 운영/휴무, 운영시간, 회차를 확인한다. | H31: 전 직원 | I31: 구현
A32: 31 | B32: Web | C32: 운영관리 | D32: 운영 스케줄 | E32: W-05-02 | F32: 요일 설정 | G32: 운영/휴무, 운영시간, 회차 기본 시간(30/40/50/60분), 최대 예약 인원을 정한다. | H32: 전 직원 | I32: 구현 | J32: 최대 인원 기본 10명, 최대 200명.
A33: 32 | B33: Web | C33: 운영관리 | D33: 운영 스케줄 | E33: W-05-03 | F33: 회차 관리 | G33: 회차별 시작·종료 시각과 예약 가능 인원을 정하고, 삭제·복사한다. | H33: 전 직원 | I33: 구현 | J33: 회차는 운영시간 안에 있어야 하고 서로 겹치면 안 된다. 번호는 시간순으로 자동 부여된다.
A34: 33 | B34: Web | C34: 운영관리 | D34: 운영 스케줄 | E34: W-05-04 | F34: 적용 시작일 지정 저장 | G34: 적용 시작일을 정하거나 '즉시 적용'으로 저장한다. | H34: 전 직원 | I34: 구현 | J34: 저장하면 새 버전이 만들어진다. 같은 시작일로 다시 저장하면 덮어쓴다.
A35: 34 | B35: Web | C35: 운영관리 | D35: 운영 스케줄 | E35: W-05-05 | F35: 스케줄 변경 이력 | G35: 이전 / 운영 중 / 예정 버전을 카드로 보고, 예정 버전을 삭제한다. | H35: 전 직원 | I35: 구현 | J35: 예정 버전을 지우면 그 기간은 이전 규칙으로 돌아간다.
A36: 35 | B36: Web | C36: 운영관리 | D36: 운영 스케줄 | E36: W-05-06 | F36: 휴무 예외 등록 | G36: 특정 기간을 휴무로 등록한다. | H36: 전 직원 | I36: 구현 | J36: 변경 사유(200자 이내) 필수. 지난 날짜는 등록할 수 없다.
A37: 36 | B37: Web | C37: 운영관리 | D37: 운영 스케줄 | E37: W-05-07 | F37: 운영시간 변경 예외 등록 | G37: 특정 기간의 운영시간과 그날 회차를 직접 정한다. | H37: 전 직원 | I37: 구현
A38: 37 | B38: Web | C38: 운영관리 | D38: 운영 스케줄 | E38: W-05-08 | F38: 운영회차 변경 예외 등록 | G38: 특정 하루의 일부 회차를 마감하거나 인원을 바꾼다. | H38: 전 직원 | I38: 구현 | J38: 하루만 지정할 수 있다.
A39: 38 | B39: Web | C39: 운영관리 | D39: 운영 스케줄 | E39: W-05-09 | F39: 예외 목록 · 삭제 | G39: 등록된 예외를 확인하고 삭제한다. | H39: 전 직원 | I39: 구현 | J39: 수정은 없고, 삭제 후 다시 등록한다. 삭제하면 평소 요일 규칙으로 돌아간다.
A40: 39 | B40: Web | C40: 운영관리 | D40: 운영 스케줄 | E40: W-05-10 | F40: 예약 보호 | G40: 예약이 이미 들어온 날짜는 예외를 등록·삭제할 수 없게 막고 문제 날짜를 알려준다. | H40: 전 직원 | I40: 구현
...

Sheet 화면목록
A1: 영역 | B1: 대메뉴 | C1: 화면ID | D1: 화면명 | E1: 접속 경로 | F1: 한 줄 설명 | G1: 사용 권한 | H1: 기능 수 | I1: 상태
A2: Web | B2: 데이터 관리 | C2: W-01 | D2: 도서 데이터 관리 | E2: /admin/book-data | F2: 도서 정보와 독서 문제를 등록·수정·삭제하는 화면 | G2: 전 직원 (편집은 본사) | H2: =COUNTIF(기능목록!$E$2:$E$141,C2&"-*") | I2: 구현
A3: Web | B3: 데이터 관리 | C3: W-02 | D3: 권장도서 순위 | E3: /admin/book-priority | F3: 학년별 권장도서 순위를 정하는 화면 (학생 추천 순서의 기준) | G3: 전 직원 (변경은 본사) | H3: =COUNTIF(기능목록!$E$2:$E$141,C3&"-*") | I3: 구현
A4: Web | B4: 데이터 관리 | C4: W-03 | D4: 레벨/뱃지 관리 | E4: /admin/level-badge | F4: 레벨·뱃지 기준을 관리하는 화면 | G4: - | H4: =COUNTIF(기능목록!$E$2:$E$141,C4&"-*") | I4: 미구현
A5: Web | B5: 운영관리 | C5: W-04 | D5: 보유도서 설정 | E5: /admin/book-stock | F5: 우리 센터가 가진 도서 수량을 관리하는 화면 | G5: 전 직원 | H5: =COUNTIF(기능목록!$E$2:$E$141,C5&"-*") | I5: 구현
A6: Web | B6: 운영관리 | C6: W-05 | D6: 운영 스케줄 | E6: /admin/operation/schedule | F6: 요일별 운영시간·회차·정원과 휴무 등 예외 일정을 설정하는 화면 | G6: 전 직원 | H6: =COUNTIF(기능목록!$E$2:$E$141,C6&"-*") | I6: 구현
A7: Web | B7: 운영관리 | C7: W-06 | D7: 학생 정보 | E7: /admin/operation/student-view | F7: 센터 학생 목록과 수강·독서·예약 정보를 보는 화면 | G7: 전 직원 | H7: =COUNTIF(기능목록!$E$2:$E$141,C7&"-*") | I7: 부분
A8: Web | B8: 운영관리 | C8: W-07 | D8: 결제 내역 | E8: /admin/payment/history-view | F8: 월별 학생 납부·이용권 현황을 보는 화면 (조회 전용) | G8: 전 직원 | H8: =COUNTIF(기능목록!$E$2:$E$141,C8&"-*") | I8: 구현
A9: Web | B9: 운영관리 | C9: W-08 | D9: 결제 이상 건 | E9: /admin/payment/review-view | F9: 사람이 직접 확인해야 하는 결제 건을 모아 보는 화면 | G9: 전 직원 | H9: =COUNTIF(기능목록!$E$2:$E$141,C9&"-*") | I9: 구현
A10: Web | B10: 모니터링 | C10: W-09 | D10: 실시간 모니터링 | E10: /admin/monitor/live-view | F10: 오늘 수업 학생의 입실·독서·문제풀이 상태를 실시간으로 보고 처리하는 화면 | G10: 전 직원 | H10: =COUNTIF(기능목록!$E$2:$E$141,C10&"-*") | I10: 구현
A11: Web | B11: 모니터링 | C11: W-10 | D11: 예약 현황 | E11: /admin/monitor/reservation-view | F11: 회차별 예약 현황 확인 및 직원 대리 예약·변경·취소 화면 | G11: 전 직원 | H11: =COUNTIF(기능목록!$E$2:$E$141,C11&"-*") | I11: 구현
A12: Web | B12: 성장관리 | C12: W-11 | D12: 독서일지 | E12: /admin/growth/diary | F12: 그날 수업 학생의 독서 태도·전달사항을 기록하는 화면 | G12: 전 직원 | H12: =COUNTIF(기능목록!$E$2:$E$141,C12&"-*") | I12: 구현
A13: Web | B13: 성장관리 | C13: W-12 | D13: 학생 성장 분석 | E13: /admin/growth/student-growth | F13: 학생별 성장 분석 화면 | G13: - | H13: =COUNTIF(기능목록!$E$2:$E$141,C13&"-*") | I13: 미구현
... A24: PWA | B24: 문제풀이 모드 | C24: P-25 | D24: 로그아웃 안내 | E24: /student/goodbye | F24: 로그아웃 후 다음에 할 일을 알려주는 화면 | G24: 학생 | H24: =COUNTIF(기능목록!$E$2:$E$141,C24&"-*") | I24: 구현

Sheet 업무규칙
A1: 규칙ID | B1: 구분 | C1: 규칙 내용 | D1: 관련 화면
A2: R-01 | B2: 도서 추천 | C2: 읽던 책이 있으면 새로 추천하지 않고 그 책을 그대로 보여준다. | D2: P-11, P-21
A3: R-02 | B3: 도서 추천 | C3: 지난번 다 못 읽고 나간 책(이어 읽기)이 있으면 새 책보다 먼저 그 책을 준다. | D3: P-11, W-09
A4: R-03 | B4: 도서 추천 | C4: 새 책은 '권장도서 순위'(올해·학생 학년 기준) 순서대로 고른다. | D4: W-02
A5: R-04 | B5: 도서 추천 | C5: 우리 센터에 빌려줄 재고가 있는 책만 추천한다. | D5: W-04
A6: R-05 | B6: 도서 추천 | C6: 이 학생에게 이미 추천한 적 있는 책은 판본이 달라도 다시 추천하지 않는다. | D6: -
A7: R-06 | B7: 도서 추천 | C7: 현재 학년 책을 모두 받았으면 한 단계 위 학년 책으로 넘어간다(최대 중등). | D7: -
A8: R-07 | B8: 도서 추천 | C8: 하루 추천 권수 제한은 없다. 분류·장르 중복을 피하는 규칙도 없다(순위표가 이미 섞여 있음). | D8: -
A9: R-08 | B9: 도서 추천 | C9: [심화 게이트] 직전에 완독한 책의 심화 문제를 오늘 한 번도 풀지 않았으면 다음 책을 주지 않는다. (완독 이력 없음 / 완독일이 오늘이 아님 / 심화 문항 없음이면 통과. 직원의 책 교체는 예외) | D9: P-11, P-21
A10: R-09 | B10: 도서 추천 | C10: 추천이 확정되면 그 즉시 책 1권을 대여 처리한다. | D10: W-04
A11: R-10 | B11: 채점 · 등급 | C11: 정답 비교와 점수 계산은 서버에서만 한다. | D11: P-22
A12: R-11 | B12: 채점 · 등급 | C12: 합격선은 전체 문항의 2/3 올림이다(12문항 → 8, 15문항 → 10). 심화는 합격선이 없다. | D12: P-22, P-23
... A48: R-47 | B48: 권한 | C48: 학년 코드는 01~07 = 초1~초6, 중등이다. | D48: -

Sheet 코드·용어
A1: 구분 | B1: 값 | C1: 의미
A2: 기본 문제 등급 | B2: 정독왕 (KING) | C2: 기본 문제 만점
A3: 기본 문제 등급 | B3: 정독 완료 (FRIEND) | C3: 합격선 이상, 만점 미만
A4: 기본 문제 등급 | B4: 완독 (RETRY) | C4: 합격선 미만 — 재도전 필요
A5: 뱃지 | B5: 1 완독 | C5: 기본 문제 첫 시도 불합격
A6: 뱃지 | B6: 2 정독 완료 | C6: 기본 문제 첫 시도 합격
A7: 뱃지 | B7: 3 정독왕 | C7: 기본 문제 첫 시도 만점
A8: 뱃지 | B8: 4 문해력 챌린저 | C8: 심화 문제 첫 시도
A9: 뱃지 | B9: 5 문해력 챔피언 | C9: 심화 문제 만점
A10: 책 상태 | B10: 읽는 중 (PENDING) | C10: 추천받아 읽고 있는 책
A11: 책 상태 | B11: 완독 (DONE) | C11: 문제를 한 번이라도 제출한 책
A12: 책 상태 | B12: 이어 읽기 (HOLD) | C12: 다 못 읽고 퇴실해 보관 중인 책
... A34: 도서 분류 | B34: 01 교과연계 | C34: 연계교과 입력
A35: 도서 분류 | B35: 02 학년필독
A36: 도서 분류 | B36: 03 권장도서
A37: 도서 분류 | B37: 04 기관추천 | C37: 추천기관 입력
A38: 도서 분류 | B38: 05 인증수상작 | C38: 수상명 입력
A39: 문제 유형 | B39: 01 이해 | C39: 기본
A40: 문제 유형 | B40: 02 표현 | C40: 기본
A41: 문제 유형 | B41: 03 논리 | C41: 기본
A42: 문제 유형 | B42: 04 사고 | C42: 기본
A43: 문제 유형 | B43: 05 감정 | C43: 기본
A44: 문제 유형 | B44: 06 어휘 | C44: 기본
A45: 문제 유형 | B45: 07 지식 | C45: 기본
A46: 문제 유형 | B46: 08 어휘심화 | C46: 심화 전용
A47: 문제 유형 | B47: 09 문법심화 | C47: 심화 전용
A48: 독서 태도 / 도움 필요 | B48: 바른 자세로 차분하게 정독했어요
A49: 독서 태도 / 도움 필요 | B49: 스스로 책 읽기를 끝까지 이어갔어요
A50: 독서 태도 / 도움 필요 | B50: 집중력이 자주 흐트러졌어요
A51: 독서 태도 / 도움 필요 | B51: 책장을 빠르게 넘기며 서둘러 읽었어요
A52: 독서 태도 / 도움 필요 | B52: 산만한 모습을 보였어요
A53: 독서 태도 / 도움 필요 | B53: (도움 필요) 혼자 읽기 어려워요! | C53: 학생 상태로 유지됨
A54: 용어 | B54: 본사 | C54: 센터코드 PUS001
A55: 용어 | B55: 지점 | C55: 본사 외 센터
A56: 용어 | B56: 출석체크 모드 | C56: 공용 기기. 입실·책 추천·퇴실만 한다.
A57: 용어 | B57: 문제풀이 모드 | C57: 학생 개인 기기. 로그인 후 문제를 푼다.
A58: 용어 | B58: 홀딩 / 이어 읽기 | C58: 다 못 읽은 책을 다음 방문 때 이어서 읽게 하는 것
A59: 용어 | B59: 심화 게이트 | C59: 심화 문제를 풀어야 다음 책을 주는 규칙

Sheet 확인 필요
A1: No | B1: 구분 | C1: 항목 | D1: 현재 상태 | E1: 영향 · 이유 | F1: 관련 화면
A2: 1 | B2: 미구현 | C2: 레벨/뱃지 관리 화면 | D2: '준비 중' 안내 화면만 있음 | E2: 레벨 기준·뱃지를 바꾸려면 개발자가 직접 수정해야 함 | F2: W-03
A3: 2 | B3: 미구현 | C3: 학생 성장 분석 화면 | D3: '준비 중' 안내 화면만 있음 | E3: 데이터는 쌓이고 있으나 볼 화면이 없음 | F3: W-12
A4: 3 | B4: 미구현 | C4: 수기 결제 등록 | D4: 버튼은 있으나 '준비 중' | E4: 현금·계좌 입금분을 시스템에 반영할 방법 없음 | F4: W-07
A5: 4 | B5: 미구현 | C5: 내 담당 학생만 보기 | D5: 학생-직원 담당 정보가 없어 비활성 | E5: 독서일지·독서 결과 발송에서 필터 불가 | F5: W-11, W-13
A6: 5 | B6: 부분 | C6: 문제풀이 기록 삭제 버튼 | D6: 기능은 있고 모니터링 화면에 버튼이 없음 | E6: 학생이 '지워달라'고 해도 직원이 화면에서 못 함 | F6: W-09
A7: 6 | B7: 부분 | C7: 분실·훼손 재고 복구 버튼 | D7: 기능은 있고 화면에 버튼이 없음 | E7: 모니터링 안내문은 '도서관리에서 복구'라고 하지만 해당 화면에 없음 | F7: W-04
A8: 7 | B8: 부분 | C8: QR 학생증 출력 | D8: 테스트용 번호 5장만 출력 | E8: 실제 학생증 발급 흐름 없음 | F8: W-06
A9: 8 | B9: 부분 | C9: 가입 링크 / 입회 등록 | D9: 링크 경로 임시, 초대코드 미처리, 직원용 화면 진입 메뉴 없음 | E9: 학부모 가입 흐름 확정 필요 | F9: W-06, W-90
A10: 9 | B10: 부분 | C10: 푸시 직접 발송 · 공통 코드 관리 | D10: 기능만 있고 화면 없음 | E10: 관리 화면이 필요한지 결정 필요 | F10: W-90
A11: 10 | B11: 부분 | C11: 이용권 소진 안내 카드(학생 메인) | D11: 이용권이 예약 때 차감되도록 바뀌어 나타날 경로가 없을 수 있음 | E11: 화면 정리 여부 결정 | F11: P-21
A12: 11 | B12: 부분 | C12: 기본+심화 합쳐 다시 풀기 | D12: 화면 흐름에서 쓰지 않는 코드가 남아 있음 | E12: 정리 대상 | F12: P-22
A13: 12 | B13: 부분 | C13: 메인으로 · 수업일지 바로가기 버튼 | D13: 연결 대상 확인 필요 | E13: 사이드바 하단 '메인으로' 버튼 동작 미확인 | F13: W-11, W-90
... A22: 21 | B22: 보안 | C22: 중복 로그인 방지가 서버 메모리에만 있음 | D22: 서버 재시작·서버 여러 대 운영 시 효력 상실 | E22: 운영 환경 확장 시 문제 | F22: P-20
